Workbook

Sheet Overview
A1: Mauritius Relative Poverty Workbook
A3: Source file | B3: source_indicators-of-relative-poverty-republic-of-mauritius.xlsx
A4: Original title | B4: Table 1 - Indicators of relative poverty, Republic of Mauritius -1996/97, 2001/02, 2006/07, 2012 and 2017
A5: Original sheets | B5: Table 1, Concepts & definitions
A6: Indicators extracted | B6: 8
A7: Survey periods | B7: 5
A8: Indicator observations | B8: 40
A9: Concept / definition entries | B9: 21
A10: Source note | B10: Source: Household Budget Survey 1996/97, 2001/02, 2006/07, 2012 and 2017
A11: Footnotes | B11: 1 : Provisional figures | 2 : See Concepts and Definitions
A14: Quick highlights from extracted data
A15: Metric | B15: 1996/97 | C15: 2017 | D15: Absolute change | E15: % change | F15: Comment
A16: Relative poverty line (Rs) per adult equivalent per month | B16: 2004 | C16: 7497 | D16: =C16-B16 -> 5493 | E16: =IFERROR(C16/B16-1,"") -> 2.741018 | F16: Relative poverty line increased strongly
A17: Estimated number of persons in relative poverty | B17: 92700 | C17: 130500 | D17: =C17-B17 -> 37800 | E17: =IFERROR(C17/B17-1,"") -> 0.40776699 | F17: Estimated persons in poverty rose
A18: Proportion of persons in relative poverty (%) | B18: 8.2 | C18: 10.3 | D18: =C18-B18 -> 2.1 | E18: =IFERROR(C18/B18-1,"") -> 0.25609756 | F18: Person poverty rate ended at 10.3%
A19: Annual amount required to move people out of relative poverty (Rs Mn) | B19: 300 | C19: 1900 | D19: =C19-B19 -> 1600 | E19: =IFERROR(C19/B19-1,"") -> 5.3333333 | F19: Annual amount required rose sharply
A22: Workbook contents
A23: Sheet | B23: Purpose | C23: Main content
A24: Indicators_Wide | B24: Cleaned core table | C24: 8 indicators across 5 survey periods plus formulas for change, CAGR, min and max
A25: Indicators_Long | B25: Tidy long-format data | C25: 40 indicator-period records with footnotes and standardized years
A26: Trend_Intervals | B26: Consecutive-period changes | C26: 32 interval-level change calculations
A27: Dashboard | B27: Visual summary | C27: Charts grouped by money, counts, rates and gap measures
A28: Concepts_Definitions | B28: Cleaned text extraction | C28: All concept and definition entries
A29: Formula_Examples | B29: Extracted formulas and worked examples | C29: Adult equivalent, PPP example, HDI example
A30: Metadata_Notes | B30: Source metadata | C30: Title, notes, footnotes and extraction details
A31: Raw_Table1 | B31: Raw source copy | C31: Copied original table sheet
A32: Raw_Concepts | B32: Raw source copy | C32: Copied original concepts sheet

Sheet Indicators_Wide
A1: Indicators of Relative Poverty - Cleaned Wide Table
A2: Metric_ID | B2: Metric | C2: Category | D2: Unit | E2: 1996/97 | F2: 2001/02 | G2: 2006/07 | H2: 2012 | I2: 2017 | J2: First value | K2: Latest value | L2: Absolute change | M2: % change | N2: CAGR | O2: Min value | P2: Min period | Q2: Max value | R2: Max period | S2: Concept link / note
E3: 1997 | F3: 2002 | G3: 2007 | H3: 2012 | I3: 2017
A4: M1 | B4: Relative poverty line (Rs) per adult equivalent per month | C4: Threshold | D4: Rs / adult equivalent / month | E4: 2004 | F4: 2804 | G4: 3821 | H4: 5652 | I4: 7497 | J4: =E4 -> 2004 | K4: =I4 -> 7497 | L4: =K4-J4 -> 5493 | M4: =IFERROR(K4/J4-1,"") -> 2.741018 | N4: =IFERROR((K4/J4)^(1/($I$3-$E$3))-1,"") -> 0.068192415 | O4: =MIN(E4:I4) -> 2004 | P4: =INDEX($E$2:$I$2,1,MATCH(O4,E4:I4,0)) -> 1996/97 | Q4: =MAX(E4:I4) -> 7497 | R4: =INDEX($E$2:$I$2,1,MATCH(Q4,E4:I4,0)) -> 2017 | S4: Relative poverty line; Adult equivalent | Footnote 2
A5: M2 | B5: Estimated number of households in relative poverty | C5: Count | D5: Households | E5: 23800 | F5: 23700 | G5: 26100 | H5: 33600 | I5: 36100 | J5: =E5 -> 23800 | K5: =I5 -> 36100 | L5: =K5-J5 -> 12300 | M5: =IFERROR(K5/J5-1,"") -> 0.51680672 | N5: =IFERROR((K5/J5)^(1/($I$3-$E$3))-1,"") -> 0.021048831 | O5: =MIN(E5:I5) -> 23700 | P5: =INDEX($E$2:$I$2,1,MATCH(O5,E5:I5,0)) -> 2001/02 | Q5: =MAX(E5:I5) -> 36100 | R5: =INDEX($E$2:$I$2,1,MATCH(Q5,E5:I5,0)) -> 2017 | S5: Poverty rate / Head count ratio
A6: M3 | B6: Proportion of households in relative poverty (%) | C6: Rate | D6: % | E6: 8.7 | F6: 7.7 | G6: 7.9 | H6: 9.4 | I6: 9.4 | J6: =E6 -> 8.7 | K6: =I6 -> 9.4 | L6: =K6-J6 -> 0.7 | M6: =IFERROR(K6/J6-1,"") -> 0.08045977 | N6: =IFERROR((K6/J6)^(1/($I$3-$E$3))-1,"") -> 0.0038768287 | O6: =MIN(E6:I6) -> 7.7 | P6: =INDEX($E$2:$I$2,1,MATCH(O6,E6:I6,0)) -> 2001/02 | Q6: =MAX(E6:I6) -> 9.4 | R6: =INDEX($E$2:$I$2,1,MATCH(Q6,E6:I6,0)) -> 2012 | S6: Poverty rate / Head count ratio
A7: M4 | B7: Estimated number of persons in relative poverty | C7: Count | D7: Persons | E7: 92700 | F7: 93800 | G7: 105200 | H7: 122700 | I7: 130500 | J7: =E7 -> 92700 | K7: =I7 -> 130500 | L7: =K7-J7 -> 37800 | M7: =IFERROR(K7/J7-1,"") -> 0.40776699 | N7: =IFERROR((K7/J7)^(1/($I$3-$E$3))-1,"") -> 0.017247284 | O7: =MIN(E7:I7) -> 92700 | P7: =INDEX($E$2:$I$2,1,MATCH(O7,E7:I7,0)) -> 1996/97 | Q7: =MAX(E7:I7) -> 130500 | R7: =INDEX($E$2:$I$2,1,MATCH(Q7,E7:I7,0)) -> 2017 | S7: Poverty rate / Head count ratio
A8: M5 | B8: Proportion of persons in relative poverty (%) | C8: Rate | D8: % | E8: 8.2 | F8: 7.8 | G8: 8.5 | H8: 9.8 | I8: 10.3 | J8: =E8 -> 8.2 | K8: =I8 -> 10.3 | L8: =K8-J8 -> 2.1 | M8: =IFERROR(K8/J8-1,"") -> 0.25609756 | N8: =IFERROR((K8/J8)^(1/($I$3-$E$3))-1,"") -> 0.01146572 | O8: =MIN(E8:I8) -> 7.8 | P8: =INDEX($E$2:$I$2,1,MATCH(O8,E8:I8,0)) -> 2001/02 | Q8: =MAX(E8:I8) -> 10.3 | R8: =INDEX($E$2:$I$2,1,MATCH(Q8,E8:I8,0)) -> 2017 | S8: Poverty rate / Head count ratio
A9: M6 | B9: Income gap ratio (%) | C9: Gap | D9: % | E9: 21 | F9: 22.6 | G9: 21.9 | H9: 24 | I9: 23.8 | J9: =E9 -> 21 | K9: =I9 -> 23.8 | L9: =K9-J9 -> 2.8 | M9: =IFERROR(K9/J9-1,"") -> 0.13333333 | N9: =IFERROR((K9/J9)^(1/($I$3-$E$3))-1,"") -> 0.0062777803 | O9: =MIN(E9:I9) -> 21 | P9: =INDEX($E$2:$I$2,1,MATCH(O9,E9:I9,0)) -> 1996/97 | Q9: =MAX(E9:I9) -> 24 | R9: =INDEX($E$2:$I$2,1,MATCH(Q9,E9:I9,0)) -> 2012 | S9: Income gap ratio (IGR)
A10: M7 | B10: Poverty gap ratio (%) | C10: Gap | D10: % | E10: 1.7 | F10: 1.8 | G10: 1.9 | H10: 2.3 | I10: 2.4 | J10: =E10 -> 1.7 | K10: =I10 -> 2.4 | L10: =K10-J10 -> 0.7 | M10: =IFERROR(K10/J10-1,"") -> 0.41176471 | N10: =IFERROR((K10/J10)^(1/($I$3-$E$3))-1,"") -> 0.017391526 | O10: =MIN(E10:I10) -> 1.7 | P10: =INDEX($E$2:$I$2,1,MATCH(O10,E10:I10,0)) -> 1996/97 | Q10: =MAX(E10:I10) -> 2.4 | R10: =INDEX($E$2:$I$2,1,MATCH(Q10,E10:I10,0)) -> 2017 | S10: Poverty gap ratio (PGR)
A11: M8 | B11: Annual amount required to move people out of relative poverty (Rs Mn) | C11: Monetary requirement | D11: Rs million | E11: 300 | F11: 450 | G11: 700 | H11: 1300 | I11: 1900 | J11: =E11 -> 300 | K11: =I11 -> 1900 | L11: =K11-J11 -> 1600 | M11: =IFERROR(K11/J11-1,"") -> 5.3333333 | N11: =IFERROR((K11/J11)^(1/($I$3-$E$3))-1,"") -> 0.096684278 | O11: =MIN(E11:I11) -> 300 | P11: =INDEX($E$2:$I$2,1,MATCH(O11,E11:I11,0)) -> 1996/97 | Q11: =MAX(E11:I11) -> 1900 | R11: =INDEX($E$2:$I$2,1,MATCH(Q11,E11:I11,0)) -> 2017 | S11: Poverty gap ratio (PGR)

Sheet Indicators_Long
A1: Indicators of Relative Poverty - Long Format
A2: Metric_ID | B2: Metric | C2: Category | D2: Unit | E2: Concept link | F2: Survey period | G2: Year end | H2: Year footnote | I2: Metric footnote | J2: Value
A3: M1 | B3: Relative poverty line (Rs) per adult equivalent per month | C3: Threshold | D3: Rs / adult equivalent / month | E3: Relative poverty line; Adult equivalent | F3: 1996/97 | G3: 2097 | I3: 2 | J3: 2004
A4: M1 | B4: Relative poverty line (Rs) per adult equivalent per month | C4: Threshold | D4: Rs / adult equivalent / month | E4: Relative poverty line; Adult equivalent | F4: 2001/02 | G4: 2002 | I4: 2 | J4: 2804
A5: M1 | B5: Relative poverty line (Rs) per adult equivalent per month | C5: Threshold | D5: Rs / adult equivalent / month | E5: Relative poverty line; Adult equivalent | F5: 2006/07 | G5: 2007 | I5: 2 | J5: 3821
A6: M1 | B6: Relative poverty line (Rs) per adult equivalent per month | C6: Threshold | D6: Rs / adult equivalent / month | E6: Relative poverty line; Adult equivalent | F6: 2012.0 | G6: 2012 | I6: 2 | J6: 5652
A7: M1 | B7: Relative poverty line (Rs) per adult equivalent per month | C7: Threshold | D7: Rs / adult equivalent / month | E7: Relative poverty line; Adult equivalent | F7: 2017 | G7: 2017 | H7: 1 | I7: 2 | J7: 7497
A8: M2 | B8: Estimated number of households in relative poverty | C8: Count | D8: Households | E8: Poverty rate / Head count ratio | F8: 1996/97 | G8: 2097 | J8: 23800
A9: M2 | B9: Estimated number of households in relative poverty | C9: Count | D9: Households | E9: Poverty rate / Head count ratio | F9: 2001/02 | G9: 2002 | J9: 23700
A10: M2 | B10: Estimated number of households in relative poverty | C10: Count | D10: Households | E10: Poverty rate / Head count ratio | F10: 2006/07 | G10: 2007 | J10: 26100
A11: M2 | B11: Estimated number of households in relative poverty | C11: Count | D11: Households | E11: Poverty rate / Head count ratio | F11: 2012.0 | G11: 2012 | J11: 33600
A12: M2 | B12: Estimated number of households in relative poverty | C12: Count | D12: Households | E12: Poverty rate / Head count ratio | F12: 2017 | G12: 2017 | H12: 1 | J12: 36100
A13: M3 | B13: Proportion of households in relative poverty (%) | C13: Rate | D13: % | E13: Poverty rate / Head count ratio | F13: 1996/97 | G13: 2097 | J13: 8.7
A14: M3 | B14: Proportion of households in relative poverty (%) | C14: Rate | D14: % | E14: Poverty rate / Head count ratio | F14: 2001/02 | G14: 2002 | J14: 7.7
A15: M3 | B15: Proportion of households in relative poverty (%) | C15: Rate | D15: % | E15: Poverty rate / Head count ratio | F15: 2006/07 | G15: 2007 | J15: 7.9
A16: M3 | B16: Proportion of households in relative poverty (%) | C16: Rate | D16: % | E16: Poverty rate / Head count ratio | F16: 2012.0 | G16: 2012 | J16: 9.4
A17: M3 | B17: Proportion of households in relative poverty (%) | C17: Rate | D17: % | E17: Poverty rate / Head count ratio | F17: 2017 | G17: 2017 | H17: 1 | J17: 9.4
A18: M4 | B18: Estimated number of persons in relative poverty | C18: Count | D18: Persons | E18: Poverty rate / Head count ratio | F18: 1996/97 | G18: 2097 | J18: 92700
A19: M4 | B19: Estimated number of persons in relative poverty | C19: Count | D19: Persons | E19: Poverty rate / Head count ratio | F19: 2001/02 | G19: 2002 | J19: 93800
A20: M4 | B20: Estimated number of persons in relative poverty | C20: Count | D20: Persons | E20: Poverty rate / Head count ratio | F20: 2006/07 | G20: 2007 | J20: 105200
A21: M4 | B21: Estimated number of persons in relative poverty | C21: Count | D21: Persons | E21: Poverty rate / Head count ratio | F21: 2012.0 | G21: 2012 | J21: 122700
A22: M4 | B22: Estimated number of persons in relative poverty | C22: Count | D22: Persons | E22: Poverty rate / Head count ratio | F22: 2017 | G22: 2017 | H22: 1 | J22: 130500
A23: M5 | B23: Proportion of persons in relative poverty (%) | C23: Rate | D23: % | E23: Poverty rate / Head count ratio | F23: 1996/97 | G23: 2097 | J23: 8.2
A24: M5 | B24: Proportion of persons in relative poverty (%) | C24: Rate | D24: % | E24: Poverty rate / Head count ratio | F24: 2001/02 | G24: 2002 | J24: 7.8
A25: M5 | B25: Proportion of persons in relative poverty (%) | C25: Rate | D25: % | E25: Poverty rate / Head count ratio | F25: 2006/07 | G25: 2007 | J25: 8.5
A26: M5 | B26: Proportion of persons in relative poverty (%) | C26: Rate | D26: % | E26: Poverty rate / Head count ratio | F26: 2012.0 | G26: 2012 | J26: 9.8
A27: M5 | B27: Proportion of persons in relative poverty (%) | C27: Rate | D27: % | E27: Poverty rate / Head count ratio | F27: 2017 | G27: 2017 | H27: 1 | J27: 10.3
A28: M6 | B28: Income gap ratio (%) | C28: Gap | D28: % | E28: Income gap ratio (IGR) | F28: 1996/97 | G28: 2097 | J28: 21
A29: M6 | B29: Income gap ratio (%) | C29: Gap | D29: % | E29: Income gap ratio (IGR) | F29: 2001/02 | G29: 2002 | J29: 22.6
A30: M6 | B30: Income gap ratio (%) | C30: Gap | D30: % | E30: Income gap ratio (IGR) | F30: 2006/07 | G30: 2007 | J30: 21.9
A31: M6 | B31: Income gap ratio (%) | C31: Gap | D31: % | E31: Income gap ratio (IGR) | F31: 2012.0 | G31: 2012 | J31: 24
A32: M6 | B32: Income gap ratio (%) | C32: Gap | D32: % | E32: Income gap ratio (IGR) | F32: 2017 | G32: 2017 | H32: 1 | J32: 23.8
A33: M7 | B33: Poverty gap ratio (%) | C33: Gap | D33: % | E33: Poverty gap ratio (PGR) | F33: 1996/97 | G33: 2097 | J33: 1.7
A34: M7 | B34: Poverty gap ratio (%) | C34: Gap | D34: % | E34: Poverty gap ratio (PGR) | F34: 2001/02 | G34: 2002 | J34: 1.8
A35: M7 | B35: Poverty gap ratio (%) | C35: Gap | D35: % | E35: Poverty gap ratio (PGR) | F35: 2006/07 | G35: 2007 | J35: 1.9
A36: M7 | B36: Poverty gap ratio (%) | C36: Gap | D36: % | E36: Poverty gap ratio (PGR) | F36: 2012.0 | G36: 2012 | J36: 2.3
A37: M7 | B37: Poverty gap ratio (%) | C37: Gap | D37: % | E37: Poverty gap ratio (PGR) | F37: 2017 | G37: 2017 | H37: 1 | J37: 2.4
A38: M8 | B38: Annual amount required to move people out of relative poverty (Rs Mn) | C38: Monetary requirement | D38: Rs million | E38: Poverty gap ratio (PGR) | F38: 1996/97 | G38: 2097 | J38: 300
A39: M8 | B39: Annual amount required to move people out of relative poverty (Rs Mn) | C39: Monetary requirement | D39: Rs million | E39: Poverty gap ratio (PGR) | F39: 2001/02 | G39: 2002 | J39: 450
A40: M8 | B40: Annual amount required to move people out of relative poverty (Rs Mn) | C40: Monetary requirement | D40: Rs million | E40: Poverty gap ratio (PGR) | F40: 2006/07 | G40: 2007 | J40: 700
...

Sheet Trend_Intervals
A1: Consecutive-Period Change Analysis
A2: Metric_ID | B2: Metric | C2: Category | D2: Unit | E2: Start period | F2: End period | G2: Years | H2: Start value | I2: End value | J2: Absolute change | K2: % change
A3: M1 | B3: Relative poverty line (Rs) per adult equivalent per month | C3: Threshold | D3: Rs / adult equivalent / month | E3: 1996/97 | F3: 2001/02 | G3: =Indicators_Wide!F$3-Indicators_Wide!E$3 -> 5 | H3: =Indicators_Wide!E4 -> 2004 | I3: =Indicators_Wide!F4 -> 2804 | J3: =I3-H3 -> 800 | K3: =IFERROR(I3/H3-1,"") -> 0.3992016
A4: M1 | B4: Relative poverty line (Rs) per adult equivalent per month | C4: Threshold | D4: Rs / adult equivalent / month | E4: 2001/02 | F4: 2006/07 | G4: =Indicators_Wide!G$3-Indicators_Wide!F$3 -> 5 | H4: =Indicators_Wide!F4 -> 2804 | I4: =Indicators_Wide!G4 -> 3821 | J4: =I4-H4 -> 1017 | K4: =IFERROR(I4/H4-1,"") -> 0.36269615
A5: M1 | B5: Relative poverty line (Rs) per adult equivalent per month | C5: Threshold | D5: Rs / adult equivalent / month | E5: 2006/07 | F5: 2012.0 | G5: =Indicators_Wide!H$3-Indicators_Wide!G$3 -> 5 | H5: =Indicators_Wide!G4 -> 3821 | I5: =Indicators_Wide!H4 -> 5652 | J5: =I5-H5 -> 1831 | K5: =IFERROR(I5/H5-1,"") -> 0.47919393
A6: M1 | B6: Relative poverty line (Rs) per adult equivalent per month | C6: Threshold | D6: Rs / adult equivalent / month | E6: 2012.0 | F6: 2017 | G6: =Indicators_Wide!I$3-Indicators_Wide!H$3 -> 5 | H6: =Indicators_Wide!H4 -> 5652 | I6: =Indicators_Wide!I4 -> 7497 | J6: =I6-H6 -> 1845 | K6: =IFERROR(I6/H6-1,"") -> 0.32643312
A7: M2 | B7: Estimated number of households in relative poverty | C7: Count | D7: Households | E7: 1996/97 | F7: 2001/02 | G7: =Indicators_Wide!F$3-Indicators_Wide!E$3 -> 5 | H7: =Indicators_Wide!E5 -> 23800 | I7: =Indicators_Wide!F5 -> 23700 | J7: =I7-H7 -> -100 | K7: =IFERROR(I7/H7-1,"") -> -0.0042016807
A8: M2 | B8: Estimated number of households in relative poverty | C8: Count | D8: Households | E8: 2001/02 | F8: 2006/07 | G8: =Indicators_Wide!G$3-Indicators_Wide!F$3 -> 5 | H8: =Indicators_Wide!F5 -> 23700 | I8: =Indicators_Wide!G5 -> 26100 | J8: =I8-H8 -> 2400 | K8: =IFERROR(I8/H8-1,"") -> 0.10126582
A9: M2 | B9: Estimated number of households in relative poverty | C9: Count | D9: Households | E9: 2006/07 | F9: 2012.0 | G9: =Indicators_Wide!H$3-Indicators_Wide!G$3 -> 5 | H9: =Indicators_Wide!G5 -> 26100 | I9: =Indicators_Wide!H5 -> 33600 | J9: =I9-H9 -> 7500 | K9: =IFERROR(I9/H9-1,"") -> 0.28735632
A10: M2 | B10: Estimated number of households in relative poverty | C10: Count | D10: Households | E10: 2012.0 | F10: 2017 | G10: =Indicators_Wide!I$3-Indicators_Wide!H$3 -> 5 | H10: =Indicators_Wide!H5 -> 33600 | I10: =Indicators_Wide!I5 -> 36100 | J10: =I10-H10 -> 2500 | K10: =IFERROR(I10/H10-1,"") -> 0.074404762
A11: M3 | B11: Proportion of households in relative poverty (%) | C11: Rate | D11: % | E11: 1996/97 | F11: 2001/02 | G11: =Indicators_Wide!F$3-Indicators_Wide!E$3 -> 5 | H11: =Indicators_Wide!E6 -> 8.7 | I11: =Indicators_Wide!F6 -> 7.7 | J11: =I11-H11 -> -1 | K11: =IFERROR(I11/H11-1,"") -> -0.11494253
A12: M3 | B12: Proportion of households in relative poverty (%) | C12: Rate | D12: % | E12: 2001/02 | F12: 2006/07 | G12: =Indicators_Wide!G$3-Indicators_Wide!F$3 -> 5 | H12: =Indicators_Wide!F6 -> 7.7 | I12: =Indicators_Wide!G6 -> 7.9 | J12: =I12-H12 -> 0.2 | K12: =IFERROR(I12/H12-1,"") -> 0.025974026
A13: M3 | B13: Proportion of households in relative poverty (%) | C13: Rate | D13: % | E13: 2006/07 | F13: 2012.0 | G13: =Indicators_Wide!H$3-Indicators_Wide!G$3 -> 5 | H13: =Indicators_Wide!G6 -> 7.9 | I13: =Indicators_Wide!H6 -> 9.4 | J13: =I13-H13 -> 1.5 | K13: =IFERROR(I13/H13-1,"") -> 0.18987342
A14: M3 | B14: Proportion of households in relative poverty (%) | C14: Rate | D14: % | E14: 2012.0 | F14: 2017 | G14: =Indicators_Wide!I$3-Indicators_Wide!H$3 -> 5 | H14: =Indicators_Wide!H6 -> 9.4 | I14: =Indicators_Wide!I6 -> 9.4 | J14: =I14-H14 -> 0 | K14: =IFERROR(I14/H14-1,"") -> 0
A15: M4 | B15: Estimated number of persons in relative poverty | C15: Count | D15: Persons | E15: 1996/97 | F15: 2001/02 | G15: =Indicators_Wide!F$3-Indicators_Wide!E$3 -> 5 | H15: =Indicators_Wide!E7 -> 92700 | I15: =Indicators_Wide!F7 -> 93800 | J15: =I15-H15 -> 1100 | K15: =IFERROR(I15/H15-1,"") -> 0.011866235
A16: M4 | B16: Estimated number of persons in relative poverty | C16: Count | D16: Persons | E16: 2001/02 | F16: 2006/07 | G16: =Indicators_Wide!G$3-Indicators_Wide!F$3 -> 5 | H16: =Indicators_Wide!F7 -> 93800 | I16: =Indicators_Wide!G7 -> 105200 | J16: =I16-H16 -> 11400 | K16: =IFERROR(I16/H16-1,"") -> 0.12153518
A17: M4 | B17: Estimated number of persons in relative poverty | C17: Count | D17: Persons | E17: 2006/07 | F17: 2012.0 | G17: =Indicators_Wide!H$3-Indicators_Wide!G$3 -> 5 | H17: =Indicators_Wide!G7 -> 105200 | I17: =Indicators_Wide!H7 -> 122700 | J17: =I17-H17 -> 17500 | K17: =IFERROR(I17/H17-1,"") -> 0.16634981
A18: M4 | B18: Estimated number of persons in relative poverty | C18: Count | D18: Persons | E18: 2012.0 | F18: 2017 | G18: =Indicators_Wide!I$3-Indicators_Wide!H$3 -> 5 | H18: =Indicators_Wide!H7 -> 122700 | I18: =Indicators_Wide!I7 -> 130500 | J18: =I18-H18 -> 7800 | K18: =IFERROR(I18/H18-1,"") -> 0.063569682
A19: M5 | B19: Proportion of persons in relative poverty (%) | C19: Rate | D19: % | E19: 1996/97 | F19: 2001/02 | G19: =Indicators_Wide!F$3-Indicators_Wide!E$3 -> 5 | H19: =Indicators_Wide!E8 -> 8.2 | I19: =Indicators_Wide!F8 -> 7.8 | J19: =I19-H19 -> -0.4 | K19: =IFERROR(I19/H19-1,"") -> -0.048780488
A20: M5 | B20: Proportion of persons in relative poverty (%) | C20: Rate | D20: % | E20: 2001/02 | F20: 2006/07 | G20: =Indicators_Wide!G$3-Indicators_Wide!F$3 -> 5 | H20: =Indicators_Wide!F8 -> 7.8 | I20: =Indicators_Wide!G8 -> 8.5 | J20: =I20-H20 -> 0.7 | K20: =IFERROR(I20/H20-1,"") -> 0.08974359
A21: M5 | B21: Proportion of persons in relative poverty (%) | C21: Rate | D21: % | E21: 2006/07 | F21: 2012.0 | G21: =Indicators_Wide!H$3-Indicators_Wide!G$3 -> 5 | H21: =Indicators_Wide!G8 -> 8.5 | I21: =Indicators_Wide!H8 -> 9.8 | J21: =I21-H21 -> 1.3 | K21: =IFERROR(I21/H21-1,"") -> 0.15294118
A22: M5 | B22: Proportion of persons in relative poverty (%) | C22: Rate | D22: % | E22: 2012.0 | F22: 2017 | G22: =Indicators_Wide!I$3-Indicators_Wide!H$3 -> 5 | H22: =Indicators_Wide!H8 -> 9.8 | I22: =Indicators_Wide!I8 -> 10.3 | J22: =I22-H22 -> 0.5 | K22: =IFERROR(I22/H22-1,"") -> 0.051020408
A23: M6 | B23: Income gap ratio (%) | C23: Gap | D23: % | E23: 1996/97 | F23: 2001/02 | G23: =Indicators_Wide!F$3-Indicators_Wide!E$3 -> 5 | H23: =Indicators_Wide!E9 -> 21 | I23: =Indicators_Wide!F9 -> 22.6 | J23: =I23-H23 -> 1.6 | K23: =IFERROR(I23/H23-1,"") -> 0.076190476
A24: M6 | B24: Income gap ratio (%) | C24: Gap | D24: % | E24: 2001/02 | F24: 2006/07 | G24: =Indicators_Wide!G$3-Indicators_Wide!F$3 -> 5 | H24: =Indicators_Wide!F9 -> 22.6 | I24: =Indicators_Wide!G9 -> 21.9 | J24: =I24-H24 -> -0.7 | K24: =IFERROR(I24/H24-1,"") -> -0.030973451
A25: M6 | B25: Income gap ratio (%) | C25: Gap | D25: % | E25: 2006/07 | F25: 2012.0 | G25: =Indicators_Wide!H$3-Indicators_Wide!G$3 -> 5 | H25: =Indicators_Wide!G9 -> 21.9 | I25: =Indicators_Wide!H9 -> 24 | J25: =I25-H25 -> 2.1 | K25: =IFERROR(I25/H25-1,"") -> 0.095890411
A26: M6 | B26: Income gap ratio (%) | C26: Gap | D26: % | E26: 2012.0 | F26: 2017 | G26: =Indicators_Wide!I$3-Indicators_Wide!H$3 -> 5 | H26: =Indicators_Wide!H9 -> 24 | I26: =Indicators_Wide!I9 -> 23.8 | J26: =I26-H26 -> -0.2 | K26: =IFERROR(I26/H26-1,"") -> -0.0083333333
A27: M7 | B27: Poverty gap ratio (%) | C27: Gap | D27: % | E27: 1996/97 | F27: 2001/02 | G27: =Indicators_Wide!F$3-Indicators_Wide!E$3 -> 5 | H27: =Indicators_Wide!E10 -> 1.7 | I27: =Indicators_Wide!F10 -> 1.8 | J27: =I27-H27 -> 0.1 | K27: =IFERROR(I27/H27-1,"") -> 0.058823529
A28: M7 | B28: Poverty gap ratio (%) | C28: Gap | D28: % | E28: 2001/02 | F28: 2006/07 | G28: =Indicators_Wide!G$3-Indicators_Wide!F$3 -> 5 | H28: =Indicators_Wide!F10 -> 1.8 | I28: =Indicators_Wide!G10 -> 1.9 | J28: =I28-H28 -> 0.1 | K28: =IFERROR(I28/H28-1,"") -> 0.055555556
A29: M7 | B29: Poverty gap ratio (%) | C29: Gap | D29: % | E29: 2006/07 | F29: 2012.0 | G29: =Indicators_Wide!H$3-Indicators_Wide!G$3 -> 5 | H29: =Indicators_Wide!G10 -> 1.9 | I29: =Indicators_Wide!H10 -> 2.3 | J29: =I29-H29 -> 0.4 | K29: =IFERROR(I29/H29-1,"") -> 0.21052632
A30: M7 | B30: Poverty gap ratio (%) | C30: Gap | D30: % | E30: 2012.0 | F30: 2017 | G30: =Indicators_Wide!I$3-Indicators_Wide!H$3 -> 5 | H30: =Indicators_Wide!H10 -> 2.3 | I30: =Indicators_Wide!I10 -> 2.4 | J30: =I30-H30 -> 0.1 | K30: =IFERROR(I30/H30-1,"") -> 0.043478261
A31: M8 | B31: Annual amount required to move people out of relative poverty (Rs Mn) | C31: Monetary requirement | D31: Rs million | E31: 1996/97 | F31: 2001/02 | G31: =Indicators_Wide!F$3-Indicators_Wide!E$3 -> 5 | H31: =Indicators_Wide!E11 -> 300 | I31: =Indicators_Wide!F11 -> 450 | J31: =I31-H31 -> 150 | K31: =IFERROR(I31/H31-1,"") -> 0.5
A32: M8 | B32: Annual amount required to move people out of relative poverty (Rs Mn) | C32: Monetary requirement | D32: Rs million | E32: 2001/02 | F32: 2006/07 | G32: =Indicators_Wide!G$3-Indicators_Wide!F$3 -> 5 | H32: =Indicators_Wide!F11 -> 450 | I32: =Indicators_Wide!G11 -> 700 | J32: =I32-H32 -> 250 | K32: =IFERROR(I32/H32-1,"") -> 0.55555556
A33: M8 | B33: Annual amount required to move people out of relative poverty (Rs Mn) | C33: Monetary requirement | D33: Rs million | E33: 2006/07 | F33: 2012.0 | G33: =Indicators_Wide!H$3-Indicators_Wide!G$3 -> 5 | H33: =Indicators_Wide!G11 -> 700 | I33: =Indicators_Wide!H11 -> 1300 | J33: =I33-H33 -> 600 | K33: =IFERROR(I33/H33-1,"") -> 0.85714286
A34: M8 | B34: Annual amount required to move people out of relative poverty (Rs Mn) | C34: Monetary requirement | D34: Rs million | E34: 2012.0 | F34: 2017 | G34: =Indicators_Wide!I$3-Indicators_Wide!H$3 -> 5 | H34: =Indicators_Wide!H11 -> 1300 | I34: =Indicators_Wide!I11 -> 1900 | J34: =I34-H34 -> 600 | K34: =IFERROR(I34/H34-1,"") -> 0.46153846

Sheet Dashboard
A1: Visual Summary
A3: Monetary indicators
A4: Metric | B4: 1996/97 | C4: 2001/02 | D4: 2006/07 | E4: 2012.0 | F4: 2017
A5: =Indicators_Wide!B4 -> Relative poverty line (Rs) per adult equivalent per month | B5: =Indicators_Wide!E4 -> 2004 | C5: =Indicators_Wide!F4 -> 2804 | D5: =Indicators_Wide!G4 -> 3821 | E5: =Indicators_Wide!H4 -> 5652 | F5: =Indicators_Wide!I4 -> 7497
A6: =Indicators_Wide!B11 -> Annual amount required to move people out of relative poverty (Rs Mn) | B6: =Indicators_Wide!E11 -> 300 | C6: =Indicators_Wide!F11 -> 450 | D6: =Indicators_Wide!G11 -> 700 | E6: =Indicators_Wide!H11 -> 1300 | F6: =Indicators_Wide!I11 -> 1900
A22: Counts of poverty
A23: Metric | B23: 1996/97 | C23: 2001/02 | D23: 2006/07 | E23: 2012.0 | F23: 2017
A24: =Indicators_Wide!B5 -> Estimated number of households in relative poverty | B24: =Indicators_Wide!E5 -> 23800 | C24: =Indicators_Wide!F5 -> 23700 | D24: =Indicators_Wide!G5 -> 26100 | E24: =Indicators_Wide!H5 -> 33600 | F24: =Indicators_Wide!I5 -> 36100
A25: =Indicators_Wide!B7 -> Estimated number of persons in relative poverty | B25: =Indicators_Wide!E7 -> 92700 | C25: =Indicators_Wide!F7 -> 93800 | D25: =Indicators_Wide!G7 -> 105200 | E25: =Indicators_Wide!H7 -> 122700 | F25: =Indicators_Wide!I7 -> 130500
A41: Poverty rates
A42: Metric | B42: 1996/97 | C42: 2001/02 | D42: 2006/07 | E42: 2012.0 | F42: 2017
A43: =Indicators_Wide!B6 -> Proportion of households in relative poverty (%) | B43: =Indicators_Wide!E6 -> 8.7 | C43: =Indicators_Wide!F6 -> 7.7 | D43: =Indicators_Wide!G6 -> 7.9 | E43: =Indicators_Wide!H6 -> 9.4 | F43: =Indicators_Wide!I6 -> 9.4
A44: =Indicators_Wide!B8 -> Proportion of persons in relative poverty (%) | B44: =Indicators_Wide!E8 -> 8.2 | C44: =Indicators_Wide!F8 -> 7.8 | D44: =Indicators_Wide!G8 -> 8.5 | E44: =Indicators_Wide!H8 -> 9.8 | F44: =Indicators_Wide!I8 -> 10.3
A60: Gap indicators
A61: Metric | B61: 1996/97 | C61: 2001/02 | D61: 2006/07 | E61: 2012.0 | F61: 2017
A62: =Indicators_Wide!B9 -> Income gap ratio (%) | B62: =Indicators_Wide!E9 -> 21 | C62: =Indicators_Wide!F9 -> 22.6 | D62: =Indicators_Wide!G9 -> 21.9 | E62: =Indicators_Wide!H9 -> 24 | F62: =Indicators_Wide!I9 -> 23.8
A63: =Indicators_Wide!B10 -> Poverty gap ratio (%) | B63: =Indicators_Wide!E10 -> 1.7 | C63: =Indicators_Wide!F10 -> 1.8 | D63: =Indicators_Wide!G10 -> 1.9 | E63: =Indicators_Wide!H10 -> 2.3 | F63: =Indicators_Wide!I10 -> 2.4

Sheet Concepts_Definitions
A1: Concepts and Definitions - Clean Extraction
A2: Concept_ID | B2: Concept | C2: Definition | D2: Comments
A3: C01 | B3: Relative poverty line | C3: It is defined in terms of the poverty of a lower income group relative to a higher income group; It is set at 50% of the median monthly household income per adult equivalent. Households with monthly income per adult equivalent below this poverty line are considered to be in relative poverty. | D3: Referenced directly or indirectly by core poverty indicators.
A4: C02 | B4: Household resources | C4: For poverty analysis, it is defined as the sum of disposable income and imputed rent i.e. the rental value of houses of non-renting households.
A5: C03 | B5: Disposable income | C5: It comprises income from employment, transfers, property, and income obtained from own produced goods; it excludes compulsory deductions such as income tax (PAYE) and contributions to pension and social security schemes.
A6: C04 | B6: Adult equivalent | C6: The number of adult equivalents (E) in a household is determined according to the Bank and Johnson's equivalence scale as follows: E = (A+0.7C)^0.7, where A = No. of adults C = No. of children (< 16 years) e.g. A household of 2 adults and 2 children = 2.4 adult equivalents
A7: C05 | B7: Poverty rate / Head count ratio | C7: Poverty rate or headcount ratio can be defined in terms of persons or households. It is the proportion of 'poor' persons or households living below the poverty line, i.e
A8: C06 | B8: Income gap ratio (IGR) | C8: It is a measure of the depth of poverty; it is the difference between the poverty line and the mean income of the poor expressed as a ratio of the poverty line as follows: IGR = Poverty line - Average income of poor | D8: Directly linked to gap metrics in Table 1.
A9: C07 | B9: Poverty gap ratio (PGR) | C9: It is a measurement of both the extent and depth of poverty; it considers both the number of poor people and how poor they are. Poverty gap ratio = Poverty rate X Income gap ratio It also indicates the total amount of money needed to bring all the poor out of poverty. Amount in Rs = PGR X Poverty line (Rs)X Number of adult equivalents in the population | D9: Directly linked to gap metrics in Table 1.
A10: C08 | B10: Absolute poverty line | C10: An absolute poverty line is fixed at a point in time and is usually updated with price changes. It allows to track the evolution of poverty over time. It is commonly estimated as the cost of basic needs of a household in terms of food, housing, clothing and other essentials for living. | D10: Referenced directly or indirectly by core poverty indicators.
A11: C09 | B11: $1.90 (PPP) a day poverty line also called the 'Extreme poverty line' | C11: This is a poverty line developed by World Bank to quantify global poverty whereby a person whose consumption expenditure is below $1.90 (PPP) a day is considered to be in extreme poverty. This extreme poverty line is measured in terms of PPP; it was originally set at $1 in 1980, then updated to $1.08 in 1993, $1.25 in 2005 and $1.90 in 2011. How to calculate the poverty rate using the $1.90 PPP a day line (i) The poverty line $1.90 (PPP) a day is converted into Mauritian Rupees using the 2011 PPP estimates for Mauritius ($1 PPP = Rs 18.2854 in 2011); (ii) The poverty line in Rs is then adjusted for local price inflation to obtain equivalent poverty line for the required year; and (iii) Finally, household survey data is used to obtain the number of persons below the poverty line. For example, the poverty rate for 2017 (as shown in Table 2) is calculated as follows: a. The poverty line of $1.90 (PPP) a day in 2011 is equivalent to Rs(1.90* 18.2854) = Rs34.74 a day in 2011. b. Upon adjusting for local price inflation of 17.7% from 2012 to 2017, the poverty line works out to Rs(34.74*1.177) = Rs 40.89 a day in 2017 c. The monthly equivalent poverty line in 2017 is estimated at Rs(40.89*365/12) or around Rs 1,245 d. Finally, the monthly expenditure of each person (estimated as its corresponding household consumption expenditure per capita) as reported at the 2017 Household Budget Survey is compared with the poverty line of Rs 1,245 to obtain the proportion of persons living below the poverty line. | D11: Referenced directly or indirectly by core poverty indicators.
A12: C10 | B12: $5.50 (PPP) a day poverty line | C12: This is a poverty line developed by world bank to quantify poverty in upper middle-income countries whereby a person whose consumption expenditure is below $5.5 (PPP) a day is considered poor. Re link: http://blogs.worldbank.org/developmenttalk/richer-array-international-poverty-lines The methodology to compile the poverty rate for this poverty line is based on the same methodology of the $1.90 (PPP) a day line. | D12: Referenced directly or indirectly by core poverty indicators.
A13: C11 | B13: Purchasing Power Parity (PPP) | C13: The Purchasing Power Parity is the amount of money in a country's currency needed to buy goods and services equivalent to what can be bought with $1 in the US. Using the 2011 International Comparison Program results, $1 PPP, based on individual household consumption expenditure data, is equivalent to Rs 18.2854.
A14: C12 | B14: Fixed threshold | C14: In the absence of an official absolute poverty line for the country, a 'Fixed threshold' has been used to track poverty over time. The fixed threshold has been determined by 'fixing' the relative poverty line in a given year, i.e. by adjusting it with price inflation to obtain the equivalent poverty lines for other years. For example, the 2017 Relative poverty lines in Table 2 have been held 'fixed' and adjusted for price changes to obtain equivalent poverty lines for 1996/97, 2001/02, 2006/07 and 2012 HBS. The poverty rates based on 'fixed thresholds' are based on household income data.
A15: C13 | B15: Household Consumption expenditure | C15: Household consumption expenditure includes: (i) money expenditure on goods and services intended for consumption by the household; and (ii) consumption of goods and services which are either own produced, received free or at reduced price by the households.
A16: C14 | B16: Share of expenditure on food on total consumption expenditure (%) | C16: The share is: Expenditure on food Total household consumption expenditure Expenditure on food comprises expenses incurred on food and non-alcoholic beverages; it also includes food consumed away from home i.e. restaurants.
A17: C15 | B17: Households | C17: A household is either: (i) a one-person household, i.e., a person who makes provision for his own food or other essentials for living without combining with any other person to form part of a multi-person household; or (ii) a multi person household, i.e, a group of two or more persons living together to make common provision for food or other essentials for living. The person in the group may pool their incomes and have a common budget to a greater or lesser extent: they may be related or unrelated persons or a combination of both.
A18: C16 | B18: Room | C18: A room is defined as a space in a housing unit enclosed by walls reaching from the floor to the ceiling or roof covering or at least to a height of two metres. It is of a size large enough to hold a bed for an adult. Its area is at least four square metres.
A19: C17 | B19: Illiteracy rate | C19: A literate person is one, who can, with understanding, both read and write a short, simple statement on his or her everyday life. Illiteracy rate (10 years and over) = Number of persons aged 10 years and over who are not literate
A20: C18 | B20: Unemployed | C20: Unemployed population refers to persons aged 16 years and above (16+) who are not working but who are looking for work and are available for work during the reference period Unemployment rate (16 years and over) = Number of unemployed aged 16 years and over Active* population aged 16 years and over * Active population is made up of employed and unemployed population.
A21: C19 | B21: Active population | C21: Active population is made up of employed and unemployed population.
A22: C20 | B22: Human Development Index (HDI) | C22: The HDI is an index developed by the UN to measure the average achievements of a country in three basic dimensions of human development, namely: (i) a long and healthy life - as measured by life expectancy (ii) knowledge - as measured by expected years of schooling and mean years of schooling; and (iii) a decent standard of living - as measured by GNI per capita. It ranges between 0 (lowest level of human development) and 1 (highest level of human development). The UN usually categorises countries into 4 equal groups according to their level of HDI as follows: Level of human development Very High HDI >= 0.800 High 0.699 < HDI < 0.800 Medium 0.549 < HDI <= 0.699 Low HDI <= 0.549 | D22: Background concept included in source definitions.
A23: C21 | B23: Calculation of HDI | C23: It is the geometric mean of the 3 dimension indices, namely (i) Health index (ii) Education index (iii) Income index, as described below. HDI and the dimension indices are calculated as: HDI = (Health index * Education index * Income index) ^ (1/3) Dimension index = actual value - minimum value maximum value - minimum value For example, 2015 HDI for Mauritius, Required data Indicator Max (observed from data by country) Minimum Mauritius Life expectancy (years) 85 20 74.6 Mean years of schooling 15 0 9.1 Expected years schooling 18 0 15.2 GNI per capita (PPP 2011 $) 75,000 100 17,948 Calculation: Health index = 74.6 - 20 = 0.840 85 - 20 Mean years of schooling index = 9.1 - 0 = 0.607 15 - 0 Expected years of schooling index = 15.2 / 18 = 0.844 Education index = 0.607 + 0.844 = 0.726 2 Income index = ln(17,948)- ln(100) = 0.784 ln (75,000) - ln(100) Human development index (HDI) = (0.840*0.726*0.784)^ (1/3) = 0.781 (approximately) | D23: Background concept included in source definitions.

Sheet Formula_Examples
A1: Extracted Formulas and Worked Examples
A3: Key formulas extracted from Concepts & Definitions | F3: Key constants and thresholds extracted
A4: Formula name | B4: Expression / rule | C4: Source concept | D4: Notes | F4: Constant | G4: Value | H4: Unit | I4: Source
A5: Relative poverty line | B5: 50% of median monthly household income per adult equivalent | C5: Relative poverty line | D5: Households below this line are considered in relative poverty. | F5: 2011 PPP conversion | G5: 18.2854 | H5: Rs per $1 PPP | I5: Purchasing Power Parity (PPP)
A6: Adult equivalent | B6: E = (A + 0.7C)^0.7 | C6: Adult equivalent | D6: A = adults; C = children under 16. | F6: Extreme poverty line | G6: 1.9 | H6: $ PPP per day | I6: $1.90 (PPP) a day poverty line
A7: Poverty gap ratio | B7: Poverty rate × Income gap ratio | C7: Poverty gap ratio (PGR) | D7: Measures extent and depth of poverty. | F7: Upper middle-income poverty line | G7: 5.5 | H7: $ PPP per day | I7: $5.50 (PPP) a day poverty line
A8: Amount needed in Rs | B8: PGR × Poverty line × Number of adult equivalents in population | C8: Poverty gap ratio (PGR) | D8: Represents total amount needed to bring all poor out of poverty. | F8: 2012 to 2017 inflation factor | G8: 1.177 | H8: multiple | I8: $1.90 (PPP) a day poverty line example
A9: HDI | B9: (Health index × Education index × Income index)^(1/3) | C9: Calculation of HDI | D9: Geometric mean of three dimension indices. | F9: 2017 monthly extreme poverty line | G9: 1245 | H9: Rs per month | I9: $1.90 (PPP) a day poverty line example
A10: Dimension index | B10: (Actual value - Minimum value) / (Maximum value - Minimum value) | C10: Calculation of HDI | D10: Used for health and education dimensions. | F10: HDI threshold - Very high | G10: 0.8 | H10: HDI | I10: Human Development Index (HDI)
F11: HDI threshold - High lower bound | G11: 0.699 | H11: HDI | I11: Human Development Index (HDI)
F12: HDI threshold - Medium lower bound | G12: 0.549 | H12: HDI | I12: Human Development Index (HDI)
A13: Worked example: 2017 extreme poverty line from PPP inputs
A14: Step | B14: Description | C14: Input / formula | D14: Value | E14: Unit
A15: Input | B15: World Bank poverty line | C15: 1.9 | D15: =C15 -> 1.9 | E15: $ PPP/day
A16: Input | B16: 2011 PPP conversion | C16: 18.2854 | D16: =C16 -> 18.2854 | E16: Rs per $1 PPP
A17: Calc | B17: Daily line in 2011 Rs | C17: =C15*C16 -> 34.74226 | D17: =C17 -> 34.74226 | E17: Rs/day
A18: Input | B18: Inflation factor 2012 to 2017 | C18: 1.177 | D18: =C18 -> 1.177 | E18: multiple
A19: Calc | B19: Daily line in 2017 Rs | C19: =D17*C18 -> 40.89164 | D19: =C19 -> 40.89164 | E19: Rs/day
A20: Calc | B20: Monthly line in 2017 Rs | C20: =D19*365/12 -> 1243.7874 | D20: =C20 -> 1243.7874 | E20: Rs/month
A23: Worked example: Mauritius 2015 HDI calculation
A24: Indicator | B24: Actual value | C24: Minimum | D24: Maximum | E24: Formula | F24: Index value | G24: Unit | H24: Notes
A25: Life expectancy | B25: 74.6 | C25: 20 | D25: 85 | E25: =(B25-C25)/(D25-C25) -> 0.84 | F25: =(B25-C25)/(D25-C25) -> 0.84 | G25: years | H25: Health index
A26: Mean years of schooling | B26: 9.1 | C26: 0 | D26: 15 | E26: =(B26-C26)/(D26-C26) -> 0.60666667 | F26: =(B26-C26)/(D26-C26) -> 0.60666667 | G26: years | H26: Education component
A27: Expected years of schooling | B27: 15.2 | C27: 0 | D27: 18 | E27: =B27/D27 -> 0.84444444 | F27: =B27/D27 -> 0.84444444 | G27: years | H27: Education component
A28: GNI per capita (PPP 2011 $) | B28: 17948 | C28: 100 | D28: 75000 | E28: =(LN(B28)-LN(C28))/(LN(D28)-LN(C28)) -> 0.78398888 | F28: =(LN(B28)-LN(C28))/(LN(D28)-LN(C28)) -> 0.78398888 | G28: PPP 2011 $ | H28: Income index
A30: Education index | B30: =(F26+F27)/2 -> 0.72555556 | C30: Derived from schooling indices
A31: HDI | B31: =(F25*B30*F28)^(1/3) -> 0.78178372 | C31: Expected approx. 0.781

Sheet Metadata_Notes
A1: Metadata and Source Notes
A3: Original workbook metadata
A4: Field | B4: Value
A5: File name | B5: source_indicators-of-relative-poverty-republic-of-mauritius.xlsx
A6: Original title | B6: Table 1 - Indicators of relative poverty, Republic of Mauritius -1996/97, 2001/02, 2006/07, 2012 and 2017
A7: Original sheets | B7: Table 1, Concepts & definitions
A8: Used range - Table 1 | B8: A2:F16
A9: Used range - Concepts & definitions | B9: A2:B23
A10: Primary source text | B10: Source: Household Budget Survey 1996/97, 2001/02, 2006/07, 2012 and 2017
A12: Extracted notes
A13: Field | B13: Value
A14: Note 1 | B14: Provisional figures
A15: Note 2 | B15: See Concepts and Definitions
A16: 2017 footnote | B16: The 2017 period header carries footnote 1.
A17: Metric footnote | B17: The relative poverty line metric carries footnote 2.
A19: Extraction details
A20: Field | B20: Value
A21: Cleaning actions | B21: Whitespace normalized; footnote digits separated from labels; long-format rows created.
A22: Derived sheets | B22: Indicators_Wide, Indicators_Long, Trend_Intervals, Dashboard, Concepts_Definitions, Formula_Examples.
A23: No external sources added | B23: Workbook content comes only from the uploaded Excel file.

Sheet Raw_Table1
A2: Table 1 - Indicators of relative poverty, Republic of Mauritius -1996/97, 2001/02, 2006/07, 2012 and 2017
B3: 1996/97 | C3: 2001/02 | D3: 2006/07 | E3: 2012 | F3: 2017 1
A4: Relative poverty2 line (Rs) per adult equivalent2 per month | B4: 2004 | C4: 2804 | D4: 3821 | E4: 5652 | F4: 7497
A5: Estimated number of households in relative poverty | B5: 23800 | C5: 23700 | D5: 26100 | E5: 33600 | F5: 36100
A6: Proportion of households in relative poverty (%) | B6: 8.7 | C6: 7.7 | D6: 7.9 | E6: 9.4 | F6: 9.4
A7: Estimated number of persons in relative poverty | B7: 92700 | C7: 93800 | D7: 105200 | E7: 122700 | F7: 130500
A8: Proportion of persons in relative poverty (%) | B8: 8.2 | C8: 7.8 | D8: 8.5 | E8: 9.8 | F8: 10.3
A9: Income gap ratio (%) | B9: 21 | C9: 22.6 | D9: 21.9 | E9: 24 | F9: 23.8
A10: Poverty gap ratio (%) | B10: 1.7 | C10: 1.8 | D10: 1.9 | E10: 2.3 | F10: 2.4
A11: Annual amount required to move people out of relative poverty (Rs Mn) | B11: 300 | C11: 450 | D11: 700 | E11: 1300 | F11: 1900
A12: Source: Household Budget Survey 1996/97, 2001/02, 2006/07, 2012 and 2017
A14: Note:
A15: 1 : Provisional figures
A16: 2 : See Concepts and Definitions

Sheet Raw_Concepts
A2: CONCEPTS & DEFINITIONS
A3: Relative poverty line | B3: It is defined in terms of the poverty of a lower income group relative to a higher income group; It is set at 50% of the median monthly household income per adult equivalent. Households with monthly income per adult equivalent below this poverty line are considered to be in relative poverty.
A4: Household resources | B4: For poverty analysis, it is defined as the sum of disposable income and imputed rent i.e. the rental value of houses of non-renting households.
A5: Disposable income | B5: It comprises income from employment, transfers, property, and income obtained from own produced goods; it excludes compulsory deductions such as income tax (PAYE) and contributions to pension and social security schemes.
A6: Adult equivalent | B6: The number of adult equivalents (E) in a household is determined according to the Bank and Johnson's equivalence scale as follows: E = (A+0.7C)^0.7, where A = No. of adults C = No. of children (< 16 years) e.g. A household of 2 adults and 2 children = 2.4 adult equivalents
A7: Poverty rate / Head count ratio | B7: Poverty rate or headcount ratio can be defined in terms of persons or households. It is the proportion of 'poor' persons or households living below the poverty line, i.e
A8: Income gap ratio (IGR) | B8: It is a measure of the depth of poverty; it is the difference between the poverty line and the mean income of the poor expressed as a ratio of the poverty line as follows: IGR = Poverty line - Average income of poor
A9: Poverty gap ratio (PGR) | B9: It is a measurement of both the extent and depth of poverty; it considers both the number of poor people and how poor they are. Poverty gap ratio = Poverty rate X Income gap ratio It also indicates the total amount of money needed to bring all the poor out of poverty. Amount in Rs = PGR X Poverty line (Rs)X Number of adult equivalents in the population
A10: Absolute poverty line | B10: An absolute poverty line is fixed at a point in time and is usually updated with price changes. It allows to track the evolution of poverty over time. It is commonly estimated as the cost of basic needs of a household in terms of food, housing, clothing and other essentials for living.
A11: $1.90 (PPP) a day poverty line also called the 'Extreme poverty line' | B11: This is a poverty line developed by World Bank to quantify global poverty whereby a person whose consumption expenditure is below $1.90 (PPP) a day is considered to be in extreme poverty. This extreme poverty line is measured in terms of PPP; it was originally set at $1 in 1980, then updated to $1.08 in 1993, $1.25 in 2005 and $1.90 in 2011. How to calculate the poverty rate using the $1.90 PPP a day line (i) The poverty line $1.90 (PPP) a day is converted into Mauritian Rupees using the 2011 PPP estimates for Mauritius ($1 PPP = Rs 18.2854 in 2011); (ii) The poverty line in Rs is then adjusted for local price inflation to obtain equivalent poverty line for the required year; and (iii) Finally, household survey data is used to obtain the number of persons below the poverty line. For example, the poverty rate for 2017 (as shown in Table 2) is calculated as follows: a. The poverty line of $1.90 (PPP) a day in 2011 is equivalent to Rs(1.90* 18.2854) = Rs34.74 a day in 2011. b. Upon adjusting for local price inflation of 17.7% from 2012 to 2017, the poverty line works out to Rs(34.74*1.177) = Rs 40.89 a day in 2017 c. The monthly equivalent poverty line in 2017 is estimated at Rs(40.89*365/12) or around Rs 1,245 d. Finally, the monthly expenditure of each person (estimated as its corresponding household consumption expenditure per capita) as reported at the 2017 Household Budget Survey is compared with the poverty line of Rs 1,245 to obtain the proportion of persons living below the poverty line.
A12: $5.50 (PPP) a day poverty line | B12: This is a poverty line developed by world bank to quantify poverty in upper middle-income countries whereby a person whose consumption expenditure is below $5.5 (PPP) a day is considered poor. Re link: http://blogs.worldbank.org/developmenttalk/richer-array-international-poverty-lines The methodology to compile the poverty rate for this poverty line is based on the same methodology of the $1.90 (PPP) a day line.
A13: Purchasing Power Parity (PPP) | B13: The Purchasing Power Parity is the amount of money in a country's currency needed to buy goods and services equivalent to what can be bought with $1 in the US. Using the 2011 International Comparison Program results, $1 PPP, based on individual household consumption expenditure data, is equivalent to Rs 18.2854.
A14: Fixed threshold | B14: In the absence of an official absolute poverty line for the country, a 'Fixed threshold' has been used to track poverty over time. The fixed threshold has been determined by 'fixing' the relative poverty line in a given year, i.e. by adjusting it with price inflation to obtain the equivalent poverty lines for other years. For example, the 2017 Relative poverty lines in Table 2 have been held 'fixed' and adjusted for price changes to obtain equivalent poverty lines for 1996/97, 2001/02, 2006/07 and 2012 HBS. The poverty rates based on 'fixed thresholds' are based on household income data.
... A23: Calculation of HDI | B23: It is the geometric mean of the 3 dimension indices, namely (i) Health index (ii) Education index (iii) Income index, as described below. HDI and the dimension indices are calculated as: HDI = (Health index * Education index * Income index) ^ (1/3) Dimension index = actual value - minimum value maximum value - minimum value For example, 2015 HDI for Mauritius, Required data Indicator Max (observed from data by country) Minimum Mauritius Life expectancy (years) 85 20 74.6 Mean years of schooling 15 0 9.1 Expected years schooling 18 0 15.2 GNI per capita (PPP 2011 $) 75,000 100 17,948 Calculation: Health index = 74.6 - 20 = 0.840 85 - 20 Mean years of schooling index = 9.1 - 0 = 0.607 15 - 0 Expected years of schooling index = 15.2 / 18 = 0.844 Education index = 0.607 + 0.844 = 0.726 2 Income index = ln(17,948)- ln(100) = 0.784 ln (75,000) - ln(100) Human development index (HDI) = (0.840*0.726*0.784)^ (1/3) = 0.781 (approximately)
